<?xml version="1.0"?>
<robot xmlns:xacro="http://www.ros.org/wiki/xacro">
    <!-- wheel-->
    <xacro:macro name="wheel_xacro" params="wheel_name xyz">
        <link name="${wheel_name}_link">
            <!-- the visual representation of the link -->
            <visual>
            <!-- 沿着自己几何中心的偏移和旋转量-->
                <origin xyz="0.0 0.0 0.0" rpy="1.57079 0.0 0.0"/>
            <!-- 几何形状-->
                <geometry>
                <!-- 圆柱体，半径0.032m，高0.04m-->
                    <cylinder radius="0.032" length="0.04"/>
                </geometry>
                <!-- 材质和颜色-->
                <material name="yellow">
                    <color rgba="1.0 1.0 0.0 0.8"/>
                </material>
            </visual>
        </link>

        <!-- 机器人的关节，用于组合机器人各个部分-->
        <joint name="${wheel_name}_joint" type="continuous">
            <!-- 连接的父链接和子链接-->
            <parent link="base_link"/>
            <child link="${wheel_name}_link"/>
            <!-- 关节的原点位置和姿态-->
            <origin xyz="${xyz}" rpy="0.0 0.0 0.0"/>
            <axis xyz="0.0 1.0 0.0"/>
        </joint>
    </xacro:macro>

</robot>
